Workbook

Sheet README
A1: Top-down grad vetting — mk1 (2026-09-27)
A3: Method | B3: Seed = Chen et al. 2021 phonon DOS (FORGE phonon reproduction). Three sweeps: forward/sideways citation lineage; Bayesian-UQ + ML-for-CMP physics groups; University of Arizona faculty. US university faculty only.
A4: Fit (1-5) | B4: Claude's judgment, EDIT FREELY (blue cells on Faculty). 5 = direct overlap with phonon-ML / Bayesian UQ AND can advise a CMP physics PhD.
A5: Physics dept | B5: Y = Physics/Applied Physics appointment; Partial = joint or listed in physics grad program (confirm sole-advising); N = other dept.
A6: Score | B6: Universities: sum of fit for Y/Partial PIs + weight x sum of fit for N PIs. Weight in cell B7.
A7: Non-physics weight | B7: 0.5
A8: Flags | B8: Gull lab moving to Warsaw; Gomez-Bombarelli possible leave; Transtrum left BYU (Tadmor row); Shuiwang Ji affiliation unverified; Biswas partial.
A9: Gaps | B9: Not exhaustive: sweeps capped ~25-36 papers each. arXiv rate limits skipped a few pages. Recruiting status is only what faculty pages state. UA score is inflated: it got a dedicated full-department sweep, other schools only appear through papers — compare on Best PI fit, not Score.
A10: Notable | B10: Zhantao Chen (seed-paper first author) is now faculty at UT Austin ME doing Bayesian Hamiltonian inference — closest match to FORGE's Laplace/HMC work.

Sheet Universities
A1: Rank | B1: University | C1: State | D1: PIs | E1: Physics PIs (Y) | F1: Partial PIs | G1: Total fit | H1: Best PI fit | I1: Score | J1: Papers
A2: =RANK(I2,$I$2:$I$29) -> 1 | B2: University of Arizona | C2: AZ | D2: =COUNTIF(Faculty!$B:$B,B2) -> 15 | E2: =COUNTIFS(Faculty!$B:$B,B2,Faculty!$E:$E,"Y") -> 8 | F2: =COUNTIFS(Faculty!$B:$B,B2,Faculty!$E:$E,"Partial") -> 3 | G2: =SUMIF(Faculty!$B:$B,B2,Faculty!$F:$F) -> 44 | H2: =_xlfn.MAXIFS(Faculty!$F:$F,Faculty!$B:$B,B2) -> 5 | I2: =SUMIFS(Faculty!$F:$F,Faculty!$B:$B,B2,Faculty!$E:$E,"Y")+SUMIFS(Faculty!$F:$F,Faculty!$B:$B,B2,Faculty!$E:$E,"Partial")+README!$B$7*SUMIFS(Faculty!$F:$F,Faculty!$B:$B,B2,Faculty!$E:$E,"N") -> 38.5 | J2: =SUMIF(Faculty!$B:$B,B2,Faculty!$K:$K) -> 24
A3: =RANK(I3,$I$2:$I$29) -> 2 | B3: U Tennessee Knoxville | C3: TN | D3: =COUNTIF(Faculty!$B:$B,B3) -> 7 | E3: =COUNTIFS(Faculty!$B:$B,B3,Faculty!$E:$E,"Y") -> 5 | F3: =COUNTIFS(Faculty!$B:$B,B3,Faculty!$E:$E,"Partial") -> 0 | G3: =SUMIF(Faculty!$B:$B,B3,Faculty!$F:$F) -> 25 | H3: =_xlfn.MAXIFS(Faculty!$F:$F,Faculty!$B:$B,B3) -> 5 | I3: =SUMIFS(Faculty!$F:$F,Faculty!$B:$B,B3,Faculty!$E:$E,"Y")+SUMIFS(Faculty!$F:$F,Faculty!$B:$B,B3,Faculty!$E:$E,"Partial")+README!$B$7*SUMIFS(Faculty!$F:$F,Faculty!$B:$B,B3,Faculty!$E:$E,"N") -> 22.5 | J3: =SUMIF(Faculty!$B:$B,B3,Faculty!$K:$K) -> 8
A4: =RANK(I4,$I$2:$I$29) -> 3 | B4: MIT | C4: MA | D4: =COUNTIF(Faculty!$B:$B,B4) -> 7 | E4: =COUNTIFS(Faculty!$B:$B,B4,Faculty!$E:$E,"Y") -> 3 | F4: =COUNTIFS(Faculty!$B:$B,B4,Faculty!$E:$E,"Partial") -> 0 | G4: =SUMIF(Faculty!$B:$B,B4,Faculty!$F:$F) -> 23 | H4: =_xlfn.MAXIFS(Faculty!$F:$F,Faculty!$B:$B,B4) -> 5 | I4: =SUMIFS(Faculty!$F:$F,Faculty!$B:$B,B4,Faculty!$E:$E,"Y")+SUMIFS(Faculty!$F:$F,Faculty!$B:$B,B4,Faculty!$E:$E,"Partial")+README!$B$7*SUMIFS(Faculty!$F:$F,Faculty!$B:$B,B4,Faculty!$E:$E,"N") -> 16.5 | J4: =SUMIF(Faculty!$B:$B,B4,Faculty!$K:$K) -> 19
A5: =RANK(I5,$I$2:$I$29) -> 4 | B5: U Florida | C5: FL | D5: =COUNTIF(Faculty!$B:$B,B5) -> 3 | E5: =COUNTIFS(Faculty!$B:$B,B5,Faculty!$E:$E,"Y") -> 2 | F5: =COUNTIFS(Faculty!$B:$B,B5,Faculty!$E:$E,"Partial") -> 0 | G5: =SUMIF(Faculty!$B:$B,B5,Faculty!$F:$F) -> 11 | H5: =_xlfn.MAXIFS(Faculty!$F:$F,Faculty!$B:$B,B5) -> 5 | I5: =SUMIFS(Faculty!$F:$F,Faculty!$B:$B,B5,Faculty!$E:$E,"Y")+SUMIFS(Faculty!$F:$F,Faculty!$B:$B,B5,Faculty!$E:$E,"Partial")+README!$B$7*SUMIFS(Faculty!$F:$F,Faculty!$B:$B,B5,Faculty!$E:$E,"N") -> 9.5 | J5: =SUMIF(Faculty!$B:$B,B5,Faculty!$K:$K) -> 4
A6: =RANK(I6,$I$2:$I$29) -> 5 | B6: UIUC | C6: IL | D6: =COUNTIF(Faculty!$B:$B,B6) -> 3 | E6: =COUNTIFS(Faculty!$B:$B,B6,Faculty!$E:$E,"Y") -> 2 | F6: =COUNTIFS(Faculty!$B:$B,B6,Faculty!$E:$E,"Partial") -> 0 | G6: =SUMIF(Faculty!$B:$B,B6,Faculty!$F:$F) -> 8 | H6: =_xlfn.MAXIFS(Faculty!$F:$F,Faculty!$B:$B,B6) -> 4 | I6: =SUMIFS(Faculty!$F:$F,Faculty!$B:$B,B6,Faculty!$E:$E,"Y")+SUMIFS(Faculty!$F:$F,Faculty!$B:$B,B6,Faculty!$E:$E,"Partial")+README!$B$7*SUMIFS(Faculty!$F:$F,Faculty!$B:$B,B6,Faculty!$E:$E,"N") -> 7.5 | J6: =SUMIF(Faculty!$B:$B,B6,Faculty!$K:$K) -> 5
A7: =RANK(I7,$I$2:$I$29) -> 6 | B7: Cornell | C7: NY | D7: =COUNTIF(Faculty!$B:$B,B7) -> 2 | E7: =COUNTIFS(Faculty!$B:$B,B7,Faculty!$E:$E,"Y") -> 1 | F7: =COUNTIFS(Faculty!$B:$B,B7,Faculty!$E:$E,"Partial") -> 0 | G7: =SUMIF(Faculty!$B:$B,B7,Faculty!$F:$F) -> 7 | H7: =_xlfn.MAXIFS(Faculty!$F:$F,Faculty!$B:$B,B7) -> 5 | I7: =SUMIFS(Faculty!$F:$F,Faculty!$B:$B,B7,Faculty!$E:$E,"Y")+SUMIFS(Faculty!$F:$F,Faculty!$B:$B,B7,Faculty!$E:$E,"Partial")+README!$B$7*SUMIFS(Faculty!$F:$F,Faculty!$B:$B,B7,Faculty!$E:$E,"N") -> 6 | J7: =SUMIF(Faculty!$B:$B,B7,Faculty!$K:$K) -> 3
A8: =RANK(I8,$I$2:$I$29) -> 7 | B8: Northeastern | C8: MA | D8: =COUNTIF(Faculty!$B:$B,B8) -> 1 | E8: =COUNTIFS(Faculty!$B:$B,B8,Faculty!$E:$E,"Y") -> 1 | F8: =COUNTIFS(Faculty!$B:$B,B8,Faculty!$E:$E,"Partial") -> 0 | G8: =SUMIF(Faculty!$B:$B,B8,Faculty!$F:$F) -> 5 | H8: =_xlfn.MAXIFS(Faculty!$F:$F,Faculty!$B:$B,B8) -> 5 | I8: =SUMIFS(Faculty!$F:$F,Faculty!$B:$B,B8,Faculty!$E:$E,"Y")+SUMIFS(Faculty!$F:$F,Faculty!$B:$B,B8,Faculty!$E:$E,"Partial")+README!$B$7*SUMIFS(Faculty!$F:$F,Faculty!$B:$B,B8,Faculty!$E:$E,"N") -> 5 | J8: =SUMIF(Faculty!$B:$B,B8,Faculty!$K:$K) -> 2
A9: =RANK(I9,$I$2:$I$29) -> 8 | B9: Caltech | C9: CA | D9: =COUNTIF(Faculty!$B:$B,B9) -> 1 | E9: =COUNTIFS(Faculty!$B:$B,B9,Faculty!$E:$E,"Y") -> 1 | F9: =COUNTIFS(Faculty!$B:$B,B9,Faculty!$E:$E,"Partial") -> 0 | G9: =SUMIF(Faculty!$B:$B,B9,Faculty!$F:$F) -> 4 | H9: =_xlfn.MAXIFS(Faculty!$F:$F,Faculty!$B:$B,B9) -> 4 | I9: =SUMIFS(Faculty!$F:$F,Faculty!$B:$B,B9,Faculty!$E:$E,"Y")+SUMIFS(Faculty!$F:$F,Faculty!$B:$B,B9,Faculty!$E:$E,"Partial")+README!$B$7*SUMIFS(Faculty!$F:$F,Faculty!$B:$B,B9,Faculty!$E:$E,"N") -> 4 | J9: =SUMIF(Faculty!$B:$B,B9,Faculty!$K:$K) -> 1
A10: =RANK(I10,$I$2:$I$29) -> 8 | B10: UC San Diego | C10: CA | D10: =COUNTIF(Faculty!$B:$B,B10) -> 1 | E10: =COUNTIFS(Faculty!$B:$B,B10,Faculty!$E:$E,"Y") -> 1 | F10: =COUNTIFS(Faculty!$B:$B,B10,Faculty!$E:$E,"Partial") -> 0 | G10: =SUMIF(Faculty!$B:$B,B10,Faculty!$F:$F) -> 4 | H10: =_xlfn.MAXIFS(Faculty!$F:$F,Faculty!$B:$B,B10) -> 4 | I10: =SUMIFS(Faculty!$F:$F,Faculty!$B:$B,B10,Faculty!$E:$E,"Y")+SUMIFS(Faculty!$F:$F,Faculty!$B:$B,B10,Faculty!$E:$E,"Partial")+README!$B$7*SUMIFS(Faculty!$F:$F,Faculty!$B:$B,B10,Faculty!$E:$E,"N") -> 4 | J10: =SUMIF(Faculty!$B:$B,B10,Faculty!$K:$K) -> 1
A11: =RANK(I11,$I$2:$I$29) -> 8 | B11: UC Davis | C11: CA | D11: =COUNTIF(Faculty!$B:$B,B11) -> 1 | E11: =COUNTIFS(Faculty!$B:$B,B11,Faculty!$E:$E,"Y") -> 1 | F11: =COUNTIFS(Faculty!$B:$B,B11,Faculty!$E:$E,"Partial") -> 0 | G11: =SUMIF(Faculty!$B:$B,B11,Faculty!$F:$F) -> 4 | H11: =_xlfn.MAXIFS(Faculty!$F:$F,Faculty!$B:$B,B11) -> 4 | I11: =SUMIFS(Faculty!$F:$F,Faculty!$B:$B,B11,Faculty!$E:$E,"Y")+SUMIFS(Faculty!$F:$F,Faculty!$B:$B,B11,Faculty!$E:$E,"Partial")+README!$B$7*SUMIFS(Faculty!$F:$F,Faculty!$B:$B,B11,Faculty!$E:$E,"N") -> 4 | J11: =SUMIF(Faculty!$B:$B,B11,Faculty!$K:$K) -> 1
A12: =RANK(I12,$I$2:$I$29) -> 8 | B12: Duke | C12: NC | D12: =COUNTIF(Faculty!$B:$B,B12) -> 1 | E12: =COUNTIFS(Faculty!$B:$B,B12,Faculty!$E:$E,"Y") -> 0 | F12: =COUNTIFS(Faculty!$B:$B,B12,Faculty!$E:$E,"Partial") -> 1 | G12: =SUMIF(Faculty!$B:$B,B12,Faculty!$F:$F) -> 4 | H12: =_xlfn.MAXIFS(Faculty!$F:$F,Faculty!$B:$B,B12) -> 4 | I12: =SUMIFS(Faculty!$F:$F,Faculty!$B:$B,B12,Faculty!$E:$E,"Y")+SUMIFS(Faculty!$F:$F,Faculty!$B:$B,B12,Faculty!$E:$E,"Partial")+README!$B$7*SUMIFS(Faculty!$F:$F,Faculty!$B:$B,B12,Faculty!$E:$E,"N") -> 4 | J12: =SUMIF(Faculty!$B:$B,B12,Faculty!$K:$K) -> 1
A13: =RANK(I13,$I$2:$I$29) -> 8 | B13: Emory | C13: GA | D13: =COUNTIF(Faculty!$B:$B,B13) -> 1 | E13: =COUNTIFS(Faculty!$B:$B,B13,Faculty!$E:$E,"Y") -> 0 | F13: =COUNTIFS(Faculty!$B:$B,B13,Faculty!$E:$E,"Partial") -> 1 | G13: =SUMIF(Faculty!$B:$B,B13,Faculty!$F:$F) -> 4 | H13: =_xlfn.MAXIFS(Faculty!$F:$F,Faculty!$B:$B,B13) -> 4 | I13: =SUMIFS(Faculty!$F:$F,Faculty!$B:$B,B13,Faculty!$E:$E,"Y")+SUMIFS(Faculty!$F:$F,Faculty!$B:$B,B13,Faculty!$E:$E,"Partial")+README!$B$7*SUMIFS(Faculty!$F:$F,Faculty!$B:$B,B13,Faculty!$E:$E,"N") -> 4 | J13: =SUMIF(Faculty!$B:$B,B13,Faculty!$K:$K) -> 0
... A29: =RANK(I29,$I$2:$I$29) -> 28 | B29: Texas A&M | C29: TX | D29: =COUNTIF(Faculty!$B:$B,B29) -> 1 | E29: =COUNTIFS(Faculty!$B:$B,B29,Faculty!$E:$E,"Y") -> 0 | F29: =COUNTIFS(Faculty!$B:$B,B29,Faculty!$E:$E,"Partial") -> 0 | G29: =SUMIF(Faculty!$B:$B,B29,Faculty!$F:$F) -> 1 | H29: =_xlfn.MAXIFS(Faculty!$F:$F,Faculty!$B:$B,B29) -> 1 | I29: =SUMIFS(Faculty!$F:$F,Faculty!$B:$B,B29,Faculty!$E:$E,"Y")+SUMIFS(Faculty!$F:$F,Faculty!$B:$B,B29,Faculty!$E:$E,"Partial")+README!$B$7*SUMIFS(Faculty!$F:$F,Faculty!$B:$B,B29,Faculty!$E:$E,"N") -> 0.5 | J29: =SUMIF(Faculty!$B:$B,B29,Faculty!$K:$K) -> 1

Sheet Faculty
A1: PI | B1: University | C1: State | D1: Department | E1: Physics dept | F1: Fit (1-5) | G1: Sweep | H1: Note / flag | I1: Page | J1: Rank in school | K1: Papers
A2: Dalziel Wilson | B2: University of Arizona | C2: AZ | D2: Optical Sciences (joint Physics) | E2: Partial | F2: 5 | G2: ua | H2: Bayesian-opt phononic nanomechanics; confirm sole Physics advising | I2: https://profiles.arizona.edu/person/dalziel | J2: =COUNTIFS($B:$B,B2,$F:$F,">"&F2)+1 -> 1 | K2: =COUNTIF(Papers!$E:$E,A2) -> 2
A3: Brian LeRoy | B3: University of Arizona | C3: AZ | D3: Physics | E3: Y | F3: 4 | G3: ua | H3: 2D/moire experiment; phonon lifetimes | I3: https://leroylab.arizona.edu/publications.html | J3: =COUNTIFS($B:$B,B3,$F:$F,">"&F3)+1 -> 2 | K3: =COUNTIF(Papers!$E:$E,A3) -> 1
A4: John Schaibley | B4: University of Arizona | C4: AZ | D4: Physics | E4: Y | F4: 4 | G4: ua | H4: TMD semiconductors; fits SST emphasis | I4: https://physics.arizona.edu/people/john-schaibley | J4: =COUNTIFS($B:$B,B4,$F:$F,">"&F4)+1 -> 2 | K4: =COUNTIF(Papers!$E:$E,A4) -> 2
A5: Pierre Deymier | B5: University of Arizona | C5: AZ | D5: Materials Sci & Eng | E5: N | F5: 4 | G5: ua | H5: UA's phonon group; needs Physics co-advisor | I5: https://mse.engineering.arizona.edu/faculty-staff | J5: =COUNTIFS($B:$B,B5,$F:$F,">"&F5)+1 -> 2 | K5: =COUNTIF(Papers!$E:$E,A5) -> 3
A6: Charles Stafford | B6: University of Arizona | C6: AZ | D6: Physics | E6: Y | F6: 3 | G6: ua | H6: Quantum heat/thermoelectric transport theory | I6: https://stafford.physics.arizona.edu/publications.html | J6: =COUNTIFS($B:$B,B6,$F:$F,">"&F6)+1 -> 5 | K6: =COUNTIF(Papers!$E:$E,A6) -> 2
A7: Zafer Mutlu | B7: University of Arizona | C7: AZ | D7: MSE / ECE / Physics | E7: Partial | F7: 3 | G7: ua | H7: GNR transistors | I7: https://zafermutlu.arizona.edu/publications | J7: =COUNTIFS($B:$B,B7,$F:$F,">"&F7)+1 -> 5 | K7: =COUNTIF(Papers!$E:$E,A7) -> 2
A8: Brian S.Y. Kim | B8: University of Arizona | C8: AZ | D8: MSE / Physics | E8: Partial | F8: 3 | G8: ua | H8: vdW / 2D semiconductors | I8: https://profiles.arizona.edu/person/briankim | J8: =COUNTIFS($B:$B,B8,$F:$F,">"&F8)+1 -> 5 | K8: =COUNTIF(Papers!$E:$E,A8) -> 1
A9: Tai Kong | B9: University of Arizona | C9: AZ | D9: Physics | E9: Y | F9: 3 | G9: ua | H9: Quantum-magnet crystal growth | I9: https://sites.google.com/view/kong-lab/publications | J9: =COUNTIFS($B:$B,B9,$F:$F,">"&F9)+1 -> 5 | K9: =COUNTIF(Papers!$E:$E,A9) -> 2
A10: Jean-Luc Bredas | B10: University of Arizona | C10: AZ | D10: Chemistry & Biochemistry | E10: N | F10: 3 | G10: ua | H10: GNN vibrational spectra; dept not confirmed on UA page | I10: https://bredators.arizona.edu/publications | J10: =COUNTIFS($B:$B,B10,$F:$F,">"&F10)+1 -> 5 | K10: =COUNTIF(Papers!$E:$E,A10) -> 1
A11: Sumit Mazumdar | B11: University of Arizona | C11: AZ | D11: Physics / Chem / OSC | E11: Y | F11: 2 | G11: ua | I11: https://physics.arizona.edu/people/sumit-mazumdar | J11: =COUNTIFS($B:$B,B11,$F:$F,">"&F11)+1 -> 10 | K11: =COUNTIF(Papers!$E:$E,A11) -> 1
A12: Mohammed Hassan | B12: University of Arizona | C12: AZ | D12: Physics (and OSC) | E12: Y | F12: 2 | G12: ua | H12: Attosecond | I12: https://sites.arizona.edu/mohammedhassan/publications/ | J12: =COUNTIFS($B:$B,B12,$F:$F,">"&F12)+1 -> 10 | K12: =COUNTIF(Papers!$E:$E,A12) -> 2
A13: Nikolay Golubev | B13: University of Arizona | C13: AZ | D13: Physics | E13: Y | F13: 2 | G13: ua | I13: https://ngolubev.com/publications/ | J13: =COUNTIFS($B:$B,B13,$F:$F,">"&F13)+1 -> 10 | K13: =COUNTIF(Papers!$E:$E,A13) -> 1
A14: Arvinder Sandhu | B14: University of Arizona | C14: AZ | D14: Physics | E14: Y | F14: 2 | G14: ua | H14: Co-author on LeRoy phonon work | I14: https://physics.arizona.edu/ | J14: =COUNTIFS($B:$B,B14,$F:$F,">"&F14)+1 -> 10 | K14: =COUNTIF(Papers!$E:$E,A14) -> 1
A15: Marat Latypov | B15: University of Arizona | C15: AZ | D15: MSE / Applied Math | E15: N | F15: 2 | G15: ua | I15: https://mse.engineering.arizona.edu/faculty-staff | J15: =COUNTIFS($B:$B,B15,$F:$F,">"&F15)+1 -> 10 | K15: =COUNTIF(Papers!$E:$E,A15) -> 1
A16: Qing Hao | B16: University of Arizona | C16: AZ | D16: Aerospace & Mechanical Eng | E16: N | F16: 2 | G16: ua | H16: Phonon thermal transport measurement | I16: https://profiles.arizona.edu/person/qinghao | J16: =COUNTIFS($B:$B,B16,$F:$F,">"&F16)+1 -> 10 | K16: =COUNTIF(Papers!$E:$E,A16) -> 2
A17: Alan Tennant | B17: U Tennessee Knoxville | C17: TN | D17: Physics & MSE | E17: Y | F17: 5 | G17: phonon-lineage | H17: Inverse Hamiltonian from neutron data; ORNL adjacent | I17: https://quantummaterials.utk.edu/affiliates/affiliates-alan-tennant/ | J17: =COUNTIFS($B:$B,B17,$F:$F,">"&F17)+1 -> 1 | K17: =COUNTIF(Papers!$E:$E,A17) -> 1
A18: Adrian Del Maestro | B18: U Tennessee Knoxville | C18: TN | D18: Physics (Head) | E18: Y | F18: 4 | G18: bayes-cmp | H18: GP ensembles for QMC/DMRG | I18: https://physics.utk.edu/people/instructional-faculty/del-maestro-adrian/ | J18: =COUNTIFS($B:$B,B18,$F:$F,">"&F18)+1 -> 2 | K18: =COUNTIF(Papers!$E:$E,A18) -> 1
A19: Yang Zhang | B19: U Tennessee Knoxville | C19: TN | D19: Physics (joint EECS) | E19: Y | F19: 4 | G19: bayes-cmp | H19: RECRUITING per page | I19: https://physics.utk.edu/people/instructional-faculty/zhang-yang/ | J19: =COUNTIFS($B:$B,B19,$F:$F,">"&F19)+1 -> 2 | K19: =COUNTIF(Papers!$E:$E,A19) -> 1
A20: Cristian Batista | B20: U Tennessee Knoxville | C20: TN | D20: Physics | E20: Y | F20: 4 | G20: bayes-cmp | H20: NN inverse neutron scattering | I20: https://physics.utk.edu/people/instructional-faculty/batista-cristian-d/ | J20: =COUNTIFS($B:$B,B20,$F:$F,">"&F20)+1 -> 2 | K20: =COUNTIF(Papers!$E:$E,A20) -> 1
A21: Steve Johnston | B21: U Tennessee Knoxville | C21: TN | D21: Physics | E21: Y | F21: 3 | G21: bayes-cmp | H21: Co-author lead: RIXS Bayesian-opt Hamiltonian inference (BNL senior) | I21: https://physics.utk.edu/ | J21: =COUNTIFS($B:$B,B21,$F:$F,">"&F21)+1 -> 5 | K21: =COUNTIF(Papers!$E:$E,A21) -> 1
A22: Sergei Kalinin | B22: U Tennessee Knoxville | C22: TN | D22: Materials Sci & Eng | E22: N | F22: 3 | G22: bayes-cmp | H22: Bayesian-opt autonomous microscopy | I22: https://tickle.utk.edu/mse/faculty/sergei-kalinin/ | J22: =COUNTIFS($B:$B,B22,$F:$F,">"&F22)+1 -> 5 | K22: =COUNTIF(Papers!$E:$E,A22) -> 2
A23: Arpan Biswas | B23: U Tennessee Knoxville | C23: TN | D23: Bredesen Center (Res. Asst. Prof.) | E23: N | F23: 2 | G23: bayes-cmp | H23: Affiliation partially verified | I23: https://bredesencenter.utk.edu/faculty/arpan-biswas/ | J23: =COUNTIFS($B:$B,B23,$F:$F,">"&F23)+1 -> 7 | K23: =COUNTIF(Papers!$E:$E,A23) -> 1
A24: Mingda Li | B24: MIT | C24: MA | D24: Nuclear Science & Eng | E24: N | F24: 5 | G24: phonon-lineage | H24: Seed-paper PI. NSE, not Physics; confirm cross-dept advising | I24: https://nse.mit.edu/people/mingda-li/ | J24: =COUNTIFS($B:$B,B24,$F:$F,">"&F24)+1 -> 1 | K24: =COUNTIF(Papers!$E:$E,A24) -> 10
A25: Tess Smidt | B25: MIT | C25: MA | D25: EECS | E25: N | F25: 4 | G25: phonon-lineage | H25: e3nn author | I25: https://www.eecs.mit.edu/people/tess-smidt/ | J25: =COUNTIFS($B:$B,B25,$F:$F,">"&F25)+1 -> 2 | K25: =COUNTIF(Papers!$E:$E,A25) -> 2
A26: Liang Fu | B26: MIT | C26: MA | D26: Physics | E26: Y | F26: 4 | G26: bayes-cmp | H26: Neural quantum states for moire/FQH | I26: https://physics.mit.edu/faculty/liang-fu/ | J26: =COUNTIFS($B:$B,B26,$F:$F,">"&F26)+1 -> 2 | K26: =COUNTIF(Papers!$E:$E,A26) -> 3
A27: Marin Soljacic | B27: MIT | C27: MA | D27: Physics | E27: Y | F27: 3 | G27: phonon-lineage | H27: Photonic DOS ML; weaker CMP fit | I27: https://physics.mit.edu/faculty/marin-soljacic/ | J27: =COUNTIFS($B:$B,B27,$F:$F,">"&F27)+1 -> 4 | K27: =COUNTIF(Papers!$E:$E,A27) -> 2
... A29: Rafael Gomez-Bombarelli | B29: MIT | C29: MA | D29: Materials Sci & Eng | E29: N | F29: 2 | G29: phonon-lineage | H29: FLAG: possible leave to Lila Sciences | I29: https://mrl.mit.edu/PIs/Rafael-Gomez-Bombarelli | J29: =COUNTIFS($B:$B,B29,$F:$F,">"&F29)+1 -> 6 | K29: =COUNTIF(Papers!$E:$E,A29) -> 1
A30: Jeffrey Grossman | B30: MIT | C30: MA | D30: Materials Sci & Eng | E30: N | F30: 2 | G30: phonon-lineage | I30: https://dmse.mit.edu/people/faculty/jeffrey-grossman/ | J30: =COUNTIFS($B:$B,B30,$F:$F,">"&F30)+1 -> 6 | K30: =COUNTIF(Papers!$E:$E,A30) -> 1
A31: Chunjing Jia | B31: U Florida | C31: FL | D31: Physics | E31: Y | F31: 5 | G31: bayes-cmp | H31: GP active learning of phase diagrams + ARPES ML | I31: https://phys.ufl.edu/people/faculty/chunjing-jia/ | J31: =COUNTIFS($B:$B,B31,$F:$F,">"&F31)+1 -> 1 | K31: =COUNTIF(Papers!$E:$E,A31) -> 2
A32: Richard Hennig | B32: U Florida | C32: FL | D32: Materials Sci & Eng | E32: N | F32: 3 | G32: phonon-lineage | H32: Electron-phonon a2F ML; cites seed | I32: https://mse.ufl.edu/people/faculty/name/richard-hennig/ | J32: =COUNTIFS($B:$B,B32,$F:$F,">"&F32)+1 -> 2 | K32: =COUNTIF(Papers!$E:$E,A32) -> 2
A33: Peter Hirschfeld | B33: U Florida | C33: FL | D33: Physics | E33: Y | F33: 3 | G33: phonon-lineage | H33: Co-author lead on Hennig superconductor ML | I33: https://phys.ufl.edu/ | J33: =COUNTIFS($B:$B,B33,$F:$F,">"&F33)+1 -> 2 | K33: =COUNTIF(Papers!$E:$E,A33) -> 0
A34: Bryan Clark | B34: UIUC | C34: IL | D34: Physics | E34: Y | F34: 4 | G34: bayes-cmp | H34: Neural quantum states | I34: https://physics.illinois.edu/people/directory/profile/bkclark | J34: =COUNTIFS($B:$B,B34,$F:$F,">"&F34)+1 -> 1 | K34: =COUNTIF(Papers!$E:$E,A34) -> 2
A35: Lucas Wagner | B35: UIUC | C35: IL | D35: Physics | E35: Y | F35: 3 | G35: bayes-cmp | I35: https://physics.illinois.edu/people/directory/profile/lkwagner | J35: =COUNTIFS($B:$B,B35,$F:$F,">"&F35)+1 -> 2 | K35: =COUNTIF(Papers!$E:$E,A35) -> 2
A36: Elif Ertekin | B36: UIUC | C36: IL | D36: Mechanical Sci & Eng | E36: N | F36: 1 | G36: phonon-lineage | H36: Weak fit | I36: https://mechse.illinois.edu/people/profile/ertekin | J36: =COUNTIFS($B:$B,B36,$F:$F,">"&F36)+1 -> 3 | K36: =COUNTIF(Papers!$E:$E,A36) -> 1
A37: Eun-Ah Kim | B37: Cornell | C37: NY | D37: Physics | E37: Y | F37: 5 | G37: phonon-lineage | H37: Strongest CMP+ML fit (XTEC on scattering data) | I37: https://physics.cornell.edu/eun-ah-kim | J37: =COUNTIFS($B:$B,B37,$F:$F,">"&F37)+1 -> 1 | K37: =COUNTIF(Papers!$E:$E,A37) -> 2
A38: Carla Gomes | B38: Cornell | C38: NY | D38: Computer Science | E38: N | F38: 2 | G38: phonon-lineage | I38: https://www.cs.cornell.edu/people/carla-gomes | J38: =COUNTIFS($B:$B,B38,$F:$F,">"&F38)+1 -> 2 | K38: =COUNTIF(Papers!$E:$E,A38) -> 1
A39: Qimin Yan | B39: Northeastern | C39: MA | D39: Physics | E39: Y | F39: 5 | G39: phonon-lineage | H39: Equivariant spectra; cites seed | I39: https://cos.northeastern.edu/wp-content/uploads/2024/12/CV_Qimin_Yan.pdf | J39: =COUNTIFS($B:$B,B39,$F:$F,">"&F39)+1 -> 1 | K39: =COUNTIF(Papers!$E:$E,A39) -> 2
A40: Marco Bernardi | B40: Caltech | C40: CA | D40: Applied Physics & Materials Sci | E40: Y | F40: 4 | G40: phonon-lineage | H40: Electron-phonon, physics-heavy | I40: https://www.aphms.caltech.edu/people/bmarco | J40: =COUNTIFS($B:$B,B40,$F:$F,">"&F40)+1 -> 1 | K40: =COUNTIF(Papers!$E:$E,A40) -> 1
A41: Yi-Zhuang You | B41: UC San Diego | C41: CA | D41: Physics | E41: Y | F41: 4 | G41: bayes-cmp | H41: Welcomes student inquiries | I41: https://everettyou.github.io/people/YZYou | J41: =COUNTIFS($B:$B,B41,$F:$F,">"&F41)+1 -> 1 | K41: =COUNTIF(Papers!$E:$E,A41) -> 1
...

Sheet Papers
A1: Title | B1: Year | C1: Venue | D1: Link | E1: Senior PI | F1: University | G1: Thread | H1: Note
A2: Direct Prediction of Phonon DOS with Euclidean Neural Networks (SEED) | B2: 2021 | C2: Advanced Science | D2: https://doi.org/10.1002/advs.202004214 | E2: Mingda Li | F2: =INDEX(Faculty!$B:$B,MATCH(E2,Faculty!$A:$A,0)) -> MIT | G2: phonon-ML | H2: Seed
A3: Virtual node GNN for full phonon prediction | B3: 2023 | C3: Nature Comput. Sci. | D3: https://arxiv.org/abs/2301.02197 | E3: Mingda Li | F3: =INDEX(Faculty!$B:$B,MATCH(E3,Faculty!$A:$A,0)) -> MIT | G3: phonon-ML | H3: DOS to full dispersion
A4: Foundation model for defect identification from vibrational spectra | B4: 2025 | C4: Matter | D4: https://arxiv.org/abs/2506.00725 | E4: Mingda Li | F4: =INDEX(Faculty!$B:$B,MATCH(E4,Faculty!$A:$A,0)) -> MIT | G4: scattering-ML
A5: AI-driven defect engineering for thermoelectrics | B5: 2025 | C5: Adv. Materials | D5: https://arxiv.org/abs/2503.19148 | E5: Mingda Li | F5: =INDEX(Faculty!$B:$B,MATCH(E5,Faculty!$A:$A,0)) -> MIT | G5: thermal-transport
A6: Universal ensemble-embedding GNN for optical spectra | B6: 2024 | C6: Advanced Materials | D6: https://doi.org/10.1002/adma.202409175 | E6: Mingda Li | F6: =INDEX(Faculty!$B:$B,MATCH(E6,Faculty!$A:$A,0)) -> MIT | G6: equivariant-NN
A7: Structural constraint integration in generative model for quantum materials | B7: 2025 | C7: Nature Materials | D7: https://doi.org/10.1038/s41563-025-02355-y | E7: Mingda Li | F7: =INDEX(Faculty!$B:$B,MATCH(E7,Faculty!$A:$A,0)) -> MIT | G7: other
A8: Machine-learning spectral indicators of topology | B8: 2022 | C8: Advanced Materials | D8: https://doi.org/10.1002/adma.202204113 | E8: Mingda Li | F8: =INDEX(Faculty!$B:$B,MATCH(E8,Faculty!$A:$A,0)) -> MIT | G8: scattering-ML
A9: ML magnetism classifiers from atomic coordinates | B9: 2022 | C9: iScience | D9: https://doi.org/10.1016/j.isci.2022.105192 | E9: Mingda Li | F9: =INDEX(Faculty!$B:$B,MATCH(E9,Faculty!$A:$A,0)) -> MIT | G9: equivariant-NN | H9: with Smidt
A10: Machine learning on neutron and x-ray scattering (review) | B10: 2021 | C10: Chem. Phys. Rev. | D10: https://arxiv.org/abs/2102.03024 | E10: Mingda Li | F10: =INDEX(Faculty!$B:$B,MATCH(E10,Faculty!$A:$A,0)) -> MIT | G10: scattering-ML
A11: Challenges and opportunities of ML on neutron and x-ray scattering | B11: 2022 | C11: Synchrotron Rad. News | D11: https://doi.org/10.1080/08940886.2022.2112498 | E11: Mingda Li | F11: =INDEX(Faculty!$B:$B,MATCH(E11,Faculty!$A:$A,0)) -> MIT | G11: scattering-ML
A12: e3nn: Euclidean neural networks | B12: 2022 | C12: arXiv | D12: https://arxiv.org/abs/2207.09453 | E12: Tess Smidt | F12: =INDEX(Faculty!$B:$B,MATCH(E12,Faculty!$A:$A,0)) -> MIT | G12: equivariant-NN | H12: Framework under the seed
A13: Phonon predictions with E(3)-equivariant GNNs (Phonax) | B13: 2024 | C13: arXiv | D13: https://arxiv.org/abs/2403.11347 | E13: Tess Smidt | F13: =INDEX(Faculty!$B:$B,MATCH(E13,Faculty!$A:$A,0)) -> MIT | G13: phonon-ML | H13: Checkelsky co-PI
A14: NequIP: E(3)-equivariant interatomic potentials | B14: 2022 | C14: Nature Commun. | D14: https://arxiv.org/abs/2101.03164 | E14: Boris Kozinsky | F14: =INDEX(Faculty!$B:$B,MATCH(E14,Faculty!$A:$A,0)) -> Harvard | G14: equivariant-NN
A15: Allegro: local equivariant representations | B15: 2023 | C15: Nature Commun. | D15: https://arxiv.org/abs/2204.05249 | E15: Boris Kozinsky | F15: =INDEX(Faculty!$B:$B,MATCH(E15,Faculty!$A:$A,0)) -> Harvard | G15: equivariant-NN
A16: Uncertainty-aware MD from Bayesian active learning (SiC) | B16: 2023 | C16: npj Comput. Mater. | D16: https://doi.org/10.1038/s41524-023-00988-8 | E16: Boris Kozinsky | F16: =INDEX(Faculty!$B:$B,MATCH(E16,Faculty!$A:$A,0)) -> Harvard | G16: thermal-transport | H16: Bayesian UQ
A17: Tensorial spectra with equivariant GNN (TSENN) | B17: 2025 | C17: Nature Commun. | D17: https://arxiv.org/abs/2505.04862 | E17: Qimin Yan | F17: =INDEX(Faculty!$B:$B,MATCH(E17,Faculty!$A:$A,0)) -> Northeastern | G17: equivariant-NN | H17: Cites seed
A18: ML for ensemble properties of disordered materials | B18: 2025 | C18: ACS Nano | D18: https://arxiv.org/abs/2506.15652 | E18: Qimin Yan | F18: =INDEX(Faculty!$B:$B,MATCH(E18,Faculty!$A:$A,0)) -> Northeastern | G18: equivariant-NN | H18: Cites seed
A19: Surrogate- and invariance-boosted contrastive learning | B19: 2021 | C19: Nature Commun. | D19: https://arxiv.org/abs/2110.08406 | E19: Marin Soljacic | F19: =INDEX(Faculty!$B:$B,MATCH(E19,Faculty!$A:$A,0)) -> MIT | G19: other | H19: Cites seed
A20: Predicting band gap from chemical composition | B20: 2025 | C20: arXiv | D20: https://arxiv.org/abs/2501.02932 | E20: Marin Soljacic | F20: =INDEX(Faculty!$B:$B,MATCH(E20,Faculty!$A:$A,0)) -> MIT | G20: other | H20: Cites seed
A21: Superconductor discovery via deep learning of electron-phonon spectral function | B21: 2024 | C21: npj Comput. Mater. | D21: https://arxiv.org/abs/2401.16611 | E21: Richard Hennig | F21: =INDEX(Faculty!$B:$B,MATCH(E21,Faculty!$A:$A,0)) -> U Florida | G21: phonon-ML | H21: Hirschfeld co-author
A22: Guided diffusion for discovery of superconductors | B22: 2025 | C22: npj Comput. Mater. | D22: https://arxiv.org/abs/2509.25186 | E22: Richard Hennig | F22: =INDEX(Faculty!$B:$B,MATCH(E22,Faculty!$A:$A,0)) -> U Florida | G22: other | H22: Cites seed
A23: Universal harmonic interatomic potential for phonons | B23: 2024 | C23: Appl. Phys. Lett. | D23: https://arxiv.org/abs/2402.11383 | E23: Yi Xia | F23: =INDEX(Faculty!$B:$B,MATCH(E23,Faculty!$A:$A,0)) -> Portland State | G23: phonon-ML | H23: Cites seed
A24: High-throughput phonons via ML universal potentials | B24: 2024 | C24: Mater. Today Phys. | D24: https://arxiv.org/abs/2407.09674 | E24: Yi Xia | F24: =INDEX(Faculty!$B:$B,MATCH(E24,Faculty!$A:$A,0)) -> Portland State | G24: phonon-ML | H24: Cites seed
A25: Phonon DOS by crystal attention GNN | B25: 2024 | C25: Mater. Today Phys. | D25: https://doi.org/10.1016/j.mtphys.2024.101632 | E25: Ming Hu | F25: =INDEX(Faculty!$B:$B,MATCH(E25,Faculty!$A:$A,0)) -> U South Carolina | G25: phonon-ML | H25: Direct competitor
A26: ML prediction of phonon scattering rates and thermal conductivity | B26: 2023 | C26: npj Comput. Mater. | D26: https://doi.org/10.1038/s41524-023-01020-9 | E26: Xiulin Ruan | F26: =INDEX(Faculty!$B:$B,MATCH(E26,Faculty!$A:$A,0)) -> Purdue | G26: thermal-transport
A27: Obscured phonon dynamics from powder INS using ML | B27: 2024 | C27: Mach. Learn.: Sci. Technol. | D27: https://doi.org/10.1088/2632-2153/ad79b6 | E27: Chen Li | F27: =INDEX(Faculty!$B:$B,MATCH(E27,Faculty!$A:$A,0)) -> UC Riverside | G27: scattering-ML | H27: VAE
A28: ML inversion of force constants from single-crystal INS | B28: 2026 | C28: Digital Discovery | D28: https://doi.org/10.1039/d6dd00008h | E28: Olivier Delaire | F28: =INDEX(Faculty!$B:$B,MATCH(E28,Faculty!$A:$A,0)) -> Duke | G28: scattering-ML
A29: RamanGPT: crystal structures to Raman spectra | B29: 2026 | C29: arXiv | D29: https://arxiv.org/abs/2606.03764 | E29: Kamal Choudhary | F29: =INDEX(Faculty!$B:$B,MATCH(E29,Faculty!$A:$A,0)) -> Johns Hopkins | G29: phonon-ML | H29: Cites seed
A30: Heat capacity estimation of complex materials | B30: 2025 | C30: Joule | D30: https://doi.org/10.1016/j.joule.2025.102054 | E30: Matthias Agne | F30: =INDEX(Faculty!$B:$B,MATCH(E30,Faculty!$A:$A,0)) -> U Oregon | G30: thermal-transport | H30: Cites seed
A31: Xtal2DoS: crystal-to-sequence DOS prediction | B31: 2023 | C31: arXiv | D31: https://arxiv.org/abs/2302.01486 | E31: Carla Gomes | F31: =INDEX(Faculty!$B:$B,MATCH(E31,Faculty!$A:$A,0)) -> Cornell | G31: phonon-ML | H31: Cites seed
A32: Interpretable unsupervised ML for x-ray diffraction (XTEC) | B32: 2022 | C32: PNAS | D32: https://doi.org/10.1073/pnas.2109665119 | E32: Eun-Ah Kim | F32: =INDEX(Faculty!$B:$B,MATCH(E32,Faculty!$A:$A,0)) -> Cornell | G32: scattering-ML
A33: Bragg glass signatures in PdxErTe3 via XRD temperature clustering | B33: 2024 | C33: Nature Physics | D33: https://doi.org/10.1038/s41567-023-02380-1 | E33: Eun-Ah Kim | F33: =INDEX(Faculty!$B:$B,MATCH(E33,Faculty!$A:$A,0)) -> Cornell | G33: scattering-ML
A34: ML + neutron scattering for Hamiltonian tuning of spin ice | B34: 2022 | C34: Commun. Materials | D34: https://doi.org/10.1038/s43246-022-00306-7 | E34: Alan Tennant | F34: =INDEX(Faculty!$B:$B,MATCH(E34,Faculty!$A:$A,0)) -> U Tennessee Knoxville | G34: scattering-ML | H34: Done at ORNL
A35: Data-driven compression of electron-phonon interactions | B35: 2024 | C35: Phys. Rev. X | D35: https://doi.org/10.1103/PhysRevX.14.021023 | E35: Marco Bernardi | F35: =INDEX(Faculty!$B:$B,MATCH(E35,Faculty!$A:$A,0)) -> Caltech | G35: phonon-ML
A36: Learning ordering in crystals with symmetry-aware GNNs | B36: 2024 | C36: arXiv | D36: https://arxiv.org/abs/2409.13851 | E36: Rafael Gomez-Bombarelli | F36: =INDEX(Faculty!$B:$B,MATCH(E36,Faculty!$A:$A,0)) -> MIT | G36: equivariant-NN | H36: Cites seed
A37: GNNs for crystal structures: capturing periodicity | B37: 2023 | C37: Science Advances | D37: https://arxiv.org/abs/2208.05039 | E37: Jeffrey Grossman | F37: =INDEX(Faculty!$B:$B,MATCH(E37,Faculty!$A:$A,0)) -> MIT | G37: equivariant-NN | H37: Cites seed
A38: Mixture-of-experts for data scarcity in materials | B38: 2022 | C38: npj Comput. Mater. | D38: https://arxiv.org/abs/2207.13880 | E38: Elif Ertekin | F38: =INDEX(Faculty!$B:$B,MATCH(E38,Faculty!$A:$A,0)) -> UIUC | G38: other
A39: Periodic graph transformers for crystal property prediction | B39: 2022 | C39: NeurIPS | D39: https://arxiv.org/abs/2209.11807 | E39: Shuiwang Ji | F39: =INDEX(Faculty!$B:$B,MATCH(E39,Faculty!$A:$A,0)) -> Texas A&M | G39: equivariant-NN
A40: Uncertainty-aware Hamiltonian inference and experimental design in quantum magnets | B40: 2026 | C40: arXiv | D40: https://arxiv.org/abs/2608.10350 | E40: Zhantao Chen | F40: =INDEX(Faculty!$B:$B,MATCH(E40,Faculty!$A:$A,0)) -> UT Austin | G40: A-bayesian | H40: Closest to FORGE Laplace/HMC
...
